Workbook

Sheet Summary
B1: Stage 1 Discover · Output schema dashboard
B2: DDD Phase 1 · Steps 01, 03 and 04 · Talentra hackathon · Schema v1.4 · every number below is counted live from the Tree, Schema register and Allowed values sheets
B4: TOTAL PARAMETERS | D4: L1 · MACRO | E4: L2 · MICRO | F4: L3 · NANO | G4: L4 · PICO | H4: ALLOWED VALUES
B5: =COUNTIF(Tree!$E$2:$E$170,1)+COUNTIF(Tree!$E$2:$E$170,2)+COUNTIF(Tree!$E$2:$E$170,3) | D5: =COUNTIF(Tree!$E$2:$E$170,1) | E5: =COUNTIF(Tree!$E$2:$E$170,2) | F5: =COUNTIF(Tree!$E$2:$E$170,3) | G5: =COUNTIFS(Tree!$E$2:$E$170,3,Tree!$J$2:$J$170,"atomic") | H5: =COUNTA('Allowed values'!$B$2:$B$195)
B6: L1 + L2 + L3 nodes in the tree | D6: Sections | E6: Parameters | F6: Sub-parameters | G6: Atomic definitions | H6: Codes in the lists
B7: ="Total parameters "&B5&" = "&D5&" Macro (L1) + "&E5&" Micro (L2) + "&F5&" Nano (L3). Each atomic item carries its L4 Pico definition ("&G5&"); "&H5&" allowed values sit inside the lists. Without the section headings the count is "&(E5+F5)&" parameters."
B9: Parameters by step and deliverable
B10: Deliverable | C10: Grain / Section ID | D10: Name | E10: L1 Macro | F10: L2 Micro | G10: L3 Nano | H10: Total parameters | I10: Allowed values | J10: L4 atomic | K10: Share of total
B11: Step 01 | C11: one row per requirement | D11: Requirements docket | E11: =COUNTIFS(Tree!$A$2:$A$170,$B11,Tree!$E$2:$E$170,1) | F11: =COUNTIFS(Tree!$A$2:$A$170,$B11,Tree!$E$2:$E$170,2) | G11: =COUNTIFS(Tree!$A$2:$A$170,$B11,Tree!$E$2:$E$170,3) | H11: =E11+F11+G11 | I11: =SUMIF($B$18:$B$35,$B11,$I$18:$I$35) | J11: =COUNTIFS(Tree!$A$2:$A$170,$B11,Tree!$E$2:$E$170,3,Tree!$J$2:$J$170,"atomic") | K11: =H11/$H$14
B12: Step 03 | C12: one row per feature; one per feature and competitor | D12: Feature discovery | E12: =COUNTIFS(Tree!$A$2:$A$170,$B12,Tree!$E$2:$E$170,1) | F12: =COUNTIFS(Tree!$A$2:$A$170,$B12,Tree!$E$2:$E$170,2) | G12: =COUNTIFS(Tree!$A$2:$A$170,$B12,Tree!$E$2:$E$170,3) | H12: =E12+F12+G12 | I12: =SUMIF($B$18:$B$35,$B12,$I$18:$I$35) | J12: =COUNTIFS(Tree!$A$2:$A$170,$B12,Tree!$E$2:$E$170,3,Tree!$J$2:$J$170,"atomic") | K12: =H12/$H$14
B13: Step 04 | C13: one row per NFR | D13: NFR register | E13: =COUNTIFS(Tree!$A$2:$A$170,$B13,Tree!$E$2:$E$170,1) | F13: =COUNTIFS(Tree!$A$2:$A$170,$B13,Tree!$E$2:$E$170,2) | G13: =COUNTIFS(Tree!$A$2:$A$170,$B13,Tree!$E$2:$E$170,3) | H13: =E13+F13+G13 | I13: =SUMIF($B$18:$B$35,$B13,$I$18:$I$35) | J13: =COUNTIFS(Tree!$A$2:$A$170,$B13,Tree!$E$2:$E$170,3,Tree!$J$2:$J$170,"atomic") | K13: =H13/$H$14
B14: Total | D14: All deliverables | E14: =SUM(E11:E13) | F14: =SUM(F11:F13) | G14: =SUM(G11:G13) | H14: =SUM(H11:H13) | I14: =SUM(I11:I13)+I37 | J14: =SUM(J11:J13) | K14: =SUM(K11:K13)
B16: Parameters by section (L1): the tree, counted | F16: Blue = Step 03 Feature Discovery (SEC-01 to 08) Green = Step 04 NFR Discovery (SEC-09 to 13) Amber = Step 01 Requirement Analysis Docket (SEC-14 to 18)
B17: Deliverable | C17: Section ID | D17: Section (L1 Macro) | E17: L1 | F17: L2 Micro | G17: L3 Nano | H17: Total parameters | I17: Allowed values | J17: L4 atomic | K17: Share of deliverable
B18: Step 03 | C18: SEC-01 | D18: Study Frame | E18: =COUNTIFS(Tree!$B$2:$B$170,$C18,Tree!$E$2:$E$170,1) | F18: =COUNTIFS(Tree!$B$2:$B$170,$C18,Tree!$E$2:$E$170,2) | G18: =COUNTIFS(Tree!$B$2:$B$170,$C18,Tree!$E$2:$E$170,3) | H18: =E18+F18+G18 | I18: =COUNTIF('Allowed values'!$E$2:$E$195,$C18) | J18: =COUNTIFS(Tree!$B$2:$B$170,$C18,Tree!$E$2:$E$170,3,Tree!$J$2:$J$170,"atomic") | K18: =H18/SUMIF($B$18:$B$35,$B18,$H$18:$H$35)
B19: Step 03 | C19: SEC-02 | D19: Competitors Studied | E19: =COUNTIFS(Tree!$B$2:$B$170,$C19,Tree!$E$2:$E$170,1) | F19: =COUNTIFS(Tree!$B$2:$B$170,$C19,Tree!$E$2:$E$170,2) | G19: =COUNTIFS(Tree!$B$2:$B$170,$C19,Tree!$E$2:$E$170,3) | H19: =E19+F19+G19 | I19: =COUNTIF('Allowed values'!$E$2:$E$195,$C19) | J19: =COUNTIFS(Tree!$B$2:$B$170,$C19,Tree!$E$2:$E$170,3,Tree!$J$2:$J$170,"atomic") | K19: =H19/SUMIF($B$18:$B$35,$B19,$H$18:$H$35)
B20: Step 03 | C20: SEC-03 | D20: Feature Inventory | E20: =COUNTIFS(Tree!$B$2:$B$170,$C20,Tree!$E$2:$E$170,1) | F20: =COUNTIFS(Tree!$B$2:$B$170,$C20,Tree!$E$2:$E$170,2) | G20: =COUNTIFS(Tree!$B$2:$B$170,$C20,Tree!$E$2:$E$170,3) | H20: =E20+F20+G20 | I20: =COUNTIF('Allowed values'!$E$2:$E$195,$C20) | J20: =COUNTIFS(Tree!$B$2:$B$170,$C20,Tree!$E$2:$E$170,3,Tree!$J$2:$J$170,"atomic") | K20: =H20/SUMIF($B$18:$B$35,$B20,$H$18:$H$35)
B21: Step 03 | C21: SEC-04 | D21: Feature Classification | E21: =COUNTIFS(Tree!$B$2:$B$170,$C21,Tree!$E$2:$E$170,1) | F21: =COUNTIFS(Tree!$B$2:$B$170,$C21,Tree!$E$2:$E$170,2) | G21: =COUNTIFS(Tree!$B$2:$B$170,$C21,Tree!$E$2:$E$170,3) | H21: =E21+F21+G21 | I21: =COUNTIF('Allowed values'!$E$2:$E$195,$C21) | J21: =COUNTIFS(Tree!$B$2:$B$170,$C21,Tree!$E$2:$E$170,3,Tree!$J$2:$J$170,"atomic") | K21: =H21/SUMIF($B$18:$B$35,$B21,$H$18:$H$35)
B22: Step 03 | C22: SEC-05 | D22: Competitor Coverage Matrix | E22: =COUNTIFS(Tree!$B$2:$B$170,$C22,Tree!$E$2:$E$170,1) | F22: =COUNTIFS(Tree!$B$2:$B$170,$C22,Tree!$E$2:$E$170,2) | G22: =COUNTIFS(Tree!$B$2:$B$170,$C22,Tree!$E$2:$E$170,3) | H22: =E22+F22+G22 | I22: =COUNTIF('Allowed values'!$E$2:$E$195,$C22) | J22: =COUNTIFS(Tree!$B$2:$B$170,$C22,Tree!$E$2:$E$170,3,Tree!$J$2:$J$170,"atomic") | K22: =H22/SUMIF($B$18:$B$35,$B22,$H$18:$H$35)
B23: Step 03 | C23: SEC-06 | D23: Requirement Trace | E23: =COUNTIFS(Tree!$B$2:$B$170,$C23,Tree!$E$2:$E$170,1) | F23: =COUNTIFS(Tree!$B$2:$B$170,$C23,Tree!$E$2:$E$170,2) | G23: =COUNTIFS(Tree!$B$2:$B$170,$C23,Tree!$E$2:$E$170,3) | H23: =E23+F23+G23 | I23: =COUNTIF('Allowed values'!$E$2:$E$195,$C23) | J23: =COUNTIFS(Tree!$B$2:$B$170,$C23,Tree!$E$2:$E$170,3,Tree!$J$2:$J$170,"atomic") | K23: =H23/SUMIF($B$18:$B$35,$B23,$H$18:$H$35)
B24: Step 03 | C24: SEC-07 | D24: Competitor Gaps | E24: =COUNTIFS(Tree!$B$2:$B$170,$C24,Tree!$E$2:$E$170,1) | F24: =COUNTIFS(Tree!$B$2:$B$170,$C24,Tree!$E$2:$E$170,2) | G24: =COUNTIFS(Tree!$B$2:$B$170,$C24,Tree!$E$2:$E$170,3) | H24: =E24+F24+G24 | I24: =COUNTIF('Allowed values'!$E$2:$E$195,$C24) | J24: =COUNTIFS(Tree!$B$2:$B$170,$C24,Tree!$E$2:$E$170,3,Tree!$J$2:$J$170,"atomic") | K24: =H24/SUMIF($B$18:$B$35,$B24,$H$18:$H$35)
B25: Step 03 | C25: SEC-08 | D25: Review Log | E25: =COUNTIFS(Tree!$B$2:$B$170,$C25,Tree!$E$2:$E$170,1) | F25: =COUNTIFS(Tree!$B$2:$B$170,$C25,Tree!$E$2:$E$170,2) | G25: =COUNTIFS(Tree!$B$2:$B$170,$C25,Tree!$E$2:$E$170,3) | H25: =E25+F25+G25 | I25: =COUNTIF('Allowed values'!$E$2:$E$195,$C25) | J25: =COUNTIFS(Tree!$B$2:$B$170,$C25,Tree!$E$2:$E$170,3,Tree!$J$2:$J$170,"atomic") | K25: =H25/SUMIF($B$18:$B$35,$B25,$H$18:$H$35)
B26: Step 04 | C26: SEC-09 | D26: NFR Identity | E26: =COUNTIFS(Tree!$B$2:$B$170,$C26,Tree!$E$2:$E$170,1) | F26: =COUNTIFS(Tree!$B$2:$B$170,$C26,Tree!$E$2:$E$170,2) | G26: =COUNTIFS(Tree!$B$2:$B$170,$C26,Tree!$E$2:$E$170,3) | H26: =E26+F26+G26 | I26: =COUNTIF('Allowed values'!$E$2:$E$195,$C26) | J26: =COUNTIFS(Tree!$B$2:$B$170,$C26,Tree!$E$2:$E$170,3,Tree!$J$2:$J$170,"atomic") | K26: =H26/SUMIF($B$18:$B$35,$B26,$H$18:$H$35)
B27: Step 04 | C27: SEC-10 | D27: NFR Target | E27: =COUNTIFS(Tree!$B$2:$B$170,$C27,Tree!$E$2:$E$170,1) | F27: =COUNTIFS(Tree!$B$2:$B$170,$C27,Tree!$E$2:$E$170,2) | G27: =COUNTIFS(Tree!$B$2:$B$170,$C27,Tree!$E$2:$E$170,3) | H27: =E27+F27+G27 | I27: =COUNTIF('Allowed values'!$E$2:$E$195,$C27) | J27: =COUNTIFS(Tree!$B$2:$B$170,$C27,Tree!$E$2:$E$170,3,Tree!$J$2:$J$170,"atomic") | K27: =H27/SUMIF($B$18:$B$35,$B27,$H$18:$H$35)
B28: Step 04 | C28: SEC-11 | D28: NFR Measurement | E28: =COUNTIFS(Tree!$B$2:$B$170,$C28,Tree!$E$2:$E$170,1) | F28: =COUNTIFS(Tree!$B$2:$B$170,$C28,Tree!$E$2:$E$170,2) | G28: =COUNTIFS(Tree!$B$2:$B$170,$C28,Tree!$E$2:$E$170,3) | H28: =E28+F28+G28 | I28: =COUNTIF('Allowed values'!$E$2:$E$195,$C28) | J28: =COUNTIFS(Tree!$B$2:$B$170,$C28,Tree!$E$2:$E$170,3,Tree!$J$2:$J$170,"atomic") | K28: =H28/SUMIF($B$18:$B$35,$B28,$H$18:$H$35)
B29: Step 04 | C29: SEC-12 | D29: NFR Basis | E29: =COUNTIFS(Tree!$B$2:$B$170,$C29,Tree!$E$2:$E$170,1) | F29: =COUNTIFS(Tree!$B$2:$B$170,$C29,Tree!$E$2:$E$170,2) | G29: =COUNTIFS(Tree!$B$2:$B$170,$C29,Tree!$E$2:$E$170,3) | H29: =E29+F29+G29 | I29: =COUNTIF('Allowed values'!$E$2:$E$195,$C29) | J29: =COUNTIFS(Tree!$B$2:$B$170,$C29,Tree!$E$2:$E$170,3,Tree!$J$2:$J$170,"atomic") | K29: =H29/SUMIF($B$18:$B$35,$B29,$H$18:$H$35)
... B35: Step 01 | C35: SEC-18 | D35: Scope Lines | E35: =COUNTIFS(Tree!$B$2:$B$170,$C35,Tree!$E$2:$E$170,1) | F35: =COUNTIFS(Tree!$B$2:$B$170,$C35,Tree!$E$2:$E$170,2) | G35: =COUNTIFS(Tree!$B$2:$B$170,$C35,Tree!$E$2:$E$170,3) | H35: =E35+F35+G35 | I35: =COUNTIF('Allowed values'!$E$2:$E$195,$C35) | J35: =COUNTIFS(Tree!$B$2:$B$170,$C35,Tree!$E$2:$E$170,3,Tree!$J$2:$J$170,"atomic") | K35: =H35/SUMIF($B$18:$B$35,$B35,$H$18:$H$35)
B36: Total | D36: All sections | E36: =SUM(E18:E35) | F36: =SUM(F18:F35) | G36: =SUM(G18:G35) | H36: =SUM(H18:H35) | I36: =SUM(I18:I35) | J36: =SUM(J18:J35)
B37: Other | D37: Shared lists (no section) | I37: =COUNTIF('Allowed values'!$E$2:$E$195,"Shared")
B39: The three deliverables for each step
B40: Step | C40: Deliverable | D40: Where it is | H40: Status
B41: 01 a | C41: Output schema definition | D41: Tree (sections 14-18), Schema register, Allowed values | H41: Done: 18 sub-parameters in two tables
B42: 01 b | C42: Schema rating scorecard | D42: Scorecard (covers the whole tree); Playbook map has the Step 01 data checks | H42: Part A done; reviewer rating pending
B43: 01 c | C43: Output document | D43: Requirements (108 FRs), Scope lines | H43: ="Draft. Playbook checks: "&COUNTIF('Playbook map'!$I$34:$I$42,"PASS")&" of 7 pass"
B44: 03 a | C44: Output schema definition | D44: Tree (sections 1-8), Schema register, Allowed values | H44: Done: v1.3
B45: 03 b | C45: Schema rating scorecard | D45: Scorecard (Part A live; Part B for a reviewer) | H45: Part A done; reviewer rating pending
B46: 03 c | C46: Output document | D46: Feature discovery, Coverage matrix, Competitors | H46: ="Draft. Playbook checks: "&COUNTIF('Playbook map'!$I$5:$I$14,"PASS")&" of 7 pass"
B47: 04 a | C47: Output schema definition | D47: Tree (sections 9-13), Schema register, Allowed values | H47: Done: 18 sub-parameters, 19 columns in the nfr table
B48: 04 b | C48: Schema rating scorecard | D48: Scorecard (covers the whole tree); Playbook map has the Step 04 data checks | H48: Part A done; reviewer rating pending
B49: 04 c | C49: Output document | D49: NFR register (20 NFRs) | H49: ="Draft. Playbook checks: "&COUNTIF('Playbook map'!$I$20:$I$26,"PASS")&" of 7 pass; 6 NFRs are proposals"

Sheet Stage 1 steps
B1: Stage 1 · Discover: the five steps
B2: From the DDD Lifecycle Detailed Playbook, page 6 ('Understand before you model'). Each step has three deliverables: a) output schema definition, b) schema rating scorecard, c) output document.
B4: Step | C4: Name | D4: Purpose | E4: Do | F4: Produce | G4: Done when | H4: Go deeper | I4: In this workbook?
B5: 01 | C5: Requirement Analysis Docket | D5: Turn the raw brief into a structured, unambiguous problem statement. | E5: Split the brief into goals, scope, out-of-scope, assumptions and open questions. Give every requirement an ID. | F5: Requirements docket: ID, statement, source, priority, ambiguity notes. | G5: Every sentence of the brief maps to a requirement ID or an explicit out-of-scope line. | H5: Turn vague words like 'fast' and 'many' into numbers. Rank open questions by design impact. | I5: YES: this workbook
B6: 02 | C6: Stakeholders, Personas and Roles | D6: Know who uses the system, who owns it and who is affected. | E6: List every human and system actor with goals, permissions and frequency of use. | F6: Persona cards and a role-permission matrix. | G6: Every requirement names at least one actor. | H6: Include edge actors: auditors, support staff, regulators, scheduled jobs. | I6: No
B7: 03 | C7: Feature Discovery | D7: Find what the product must do and what market leaders already do. | E7: Study at least three competing products. Classify features as must-have, should-have or differentiator. | F7: Feature inventory with a competitor coverage matrix. | G7: Every feature traces to a requirement or is flagged as a new insight. | H7: Find what competitors lack and argue why it matters. | I7: YES: this workbook
B8: 04 | C8: NFR Discovery | D8: Fix measurable quality targets before the design locks them out. | E8: Set targets for scale, response time, availability, security, privacy, compliance and accessibility. | F8: NFR register: ID, metric, target, how it is measured. | G8: Every NFR has a number and a test method. | H8: Derive targets from volumes, not guesses. Name the regulations that apply, such as the DPDP Act 2023. | I8: YES: this workbook
B9: 05 | C9: Business Workflow Analysis | D9: Map how work actually flows from end to end. | E9: For each core workflow record trigger, steps, actors, decisions, exceptions and outputs. | F9: Workflow diagrams and an exception catalogue. | G9: Every must-have feature appears in at least one workflow. | H9: Map cancel, refund, retry and timeout paths, not only the happy path. | I9: No
B11: Exit gate G1 · Problem understood: every requirement has an ID and an actor. Every NFR has a numeric target. Every must-have feature appears in a workflow.
B13: Deliverables per step
B14: Step | C14: Name | D14: a) Output schema definition | E14: b) Schema rating scorecard | F14: c) Output document
B15: 01 | C15: Requirement Analysis Docket | D15: Tree sections 14-18, Schema register, Allowed values | E15: Scorecard | F15: Requirements, Scope lines
B16: 02 | C16: Stakeholders, Personas and Roles | D16: Not in this workbook | E16: Not in this workbook | F16: Not in this workbook
B17: 03 | C17: Feature Discovery | D17: Tree sections 1-8, Schema register, Allowed values | E17: Scorecard | F17: Feature discovery, Coverage matrix, Competitors
B18: 04 | C18: NFR Discovery | D18: Tree sections 9-13, Schema register, Allowed values | E18: Scorecard | F18: NFR register
B19: 05 | C19: Business Workflow Analysis | D19: Not in this workbook | E19: Not in this workbook | F19: Not in this workbook

Sheet Playbook map
B1: Step 03 playbook map
B2: Each phrase of the Step 03 row, the section that answers it, how many parameters sit under it (live) and a live check where the data allows one.
B4: Playbook column | C4: Playbook words | D4: Section ID | E4: Section | F4: Parameters (L2+L3) | G4: Live check | H4: Value | I4: Result
B5: Purpose | C5: Find what the product must do | D5: SEC-03 | E5: =INDEX(Tree!$C$2:$C$170,MATCH(D5,Tree!$B$2:$B$170,0)) | F5: =COUNTIFS(Tree!$B$2:$B$170,D5,Tree!$E$2:$E$170,2)+COUNTIFS(Tree!$B$2:$B$170,D5,Tree!$E$2:$E$170,3) | G5: Features recorded (one row each) | H5: =COUNTA('Feature discovery'!$A$4:$A$179) | I5: =IF(H5>=1,"PASS","FAIL")
B6: Purpose | C6: ...and what market leaders already do | D6: SEC-05 | E6: =INDEX(Tree!$C$2:$C$170,MATCH(D6,Tree!$B$2:$B$170,0)) | F6: =COUNTIFS(Tree!$B$2:$B$170,D6,Tree!$E$2:$E$170,2)+COUNTIFS(Tree!$B$2:$B$170,D6,Tree!$E$2:$E$170,3) | G6: Features with a coverage row | H6: =COUNTA('Coverage matrix'!$A$4:$A$126) | I6: =IF(H6>=1,"PASS","FAIL")
B7: Do | C7: Study at least three competing products | D7: SEC-02 | E7: =INDEX(Tree!$C$2:$C$170,MATCH(D7,Tree!$B$2:$B$170,0)) | F7: =COUNTIFS(Tree!$B$2:$B$170,D7,Tree!$E$2:$E$170,2)+COUNTIFS(Tree!$B$2:$B$170,D7,Tree!$E$2:$E$170,3) | G7: Competitors studied (needs 3 or more) | H7: =COUNTA(Competitors!$A$4:$A$7) | I7: =IF(H7>=3,"PASS","FAIL")
B8: Do | C8: Classify features as must-have, should-have or differentiator | D8: SEC-04 | E8: =INDEX(Tree!$C$2:$C$170,MATCH(D8,Tree!$B$2:$B$170,0)) | F8: =COUNTIFS(Tree!$B$2:$B$170,D8,Tree!$E$2:$E$170,2)+COUNTIFS(Tree!$B$2:$B$170,D8,Tree!$E$2:$E$170,3) | G8: Features with a class other than the three (needs 0) | H8: =COUNTA('Feature discovery'!$K$4:$K$179)-COUNTIF('Feature discovery'!$K$4:$K$179,"MUST-HAVE")-COUNTIF('Feature discovery'!$K$4:$K$179,"SHOULD-HAVE")-COUNTIF('Feature discovery'!$K$4:$K$179,"DIFFERENTIATOR") | I8: =IF(H8=0,"PASS","FAIL")
B9: Produce | C9: Feature inventory ... | D9: SEC-03 | E9: =INDEX(Tree!$C$2:$C$170,MATCH(D9,Tree!$B$2:$B$170,0)) | F9: =COUNTIFS(Tree!$B$2:$B$170,D9,Tree!$E$2:$E$170,2)+COUNTIFS(Tree!$B$2:$B$170,D9,Tree!$E$2:$E$170,3) | G9: Feature discovery rows | H9: =COUNTA('Feature discovery'!$A$4:$A$179) | I9: =IF(H9>=1,"PASS","FAIL")
B10: Produce | C10: ... with a competitor coverage matrix | D10: SEC-05 | E10: =INDEX(Tree!$C$2:$C$170,MATCH(D10,Tree!$B$2:$B$170,0)) | F10: =COUNTIFS(Tree!$B$2:$B$170,D10,Tree!$E$2:$E$170,2)+COUNTIFS(Tree!$B$2:$B$170,D10,Tree!$E$2:$E$170,3) | G10: Coverage matrix rows | H10: =COUNTA('Coverage matrix'!$A$4:$A$126) | I10: =IF(H10>=1,"PASS","FAIL")
B11: Done when | C11: Every feature traces to a requirement or is flagged as a new insight | D11: SEC-06 | E11: =INDEX(Tree!$C$2:$C$170,MATCH(D11,Tree!$B$2:$B$170,0)) | F11: =COUNTIFS(Tree!$B$2:$B$170,D11,Tree!$E$2:$E$170,2)+COUNTIFS(Tree!$B$2:$B$170,D11,Tree!$E$2:$E$170,3) | G11: Features with neither (needs 0) | H11: =COUNTA('Feature discovery'!$A$4:$A$179)-COUNTIF('Feature discovery'!$S$4:$S$179,"Traced*")-COUNTIF('Feature discovery'!$S$4:$S$179,"NEW INSIGHT") | I11: =IF(H11=0,"PASS","FAIL")
B12: Go deeper | C12: Find what competitors lack and argue why it matters | D12: SEC-07 | E12: =INDEX(Tree!$C$2:$C$170,MATCH(D12,Tree!$B$2:$B$170,0)) | F12: =COUNTIFS(Tree!$B$2:$B$170,D12,Tree!$E$2:$E$170,2)+COUNTIFS(Tree!$B$2:$B$170,D12,Tree!$E$2:$E$170,3) | G12: Not checked by a formula: needs a person to judge the arguments | I12: person
B13: Not in the playbook row | C13: Context of the study (product, method, version, date) | D13: SEC-01 | E13: =INDEX(Tree!$C$2:$C$170,MATCH(D13,Tree!$B$2:$B$170,0)) | F13: =COUNTIFS(Tree!$B$2:$B$170,D13,Tree!$E$2:$E$170,2)+COUNTIFS(Tree!$B$2:$B$170,D13,Tree!$E$2:$E$170,3) | G13: Added so the study can be repeated | I13: person
B14: Not in the playbook row | C14: Review, review, review loop (Subramanian's transcript) | D14: SEC-08 | E14: =INDEX(Tree!$C$2:$C$170,MATCH(D14,Tree!$B$2:$B$170,0)) | F14: =COUNTIFS(Tree!$B$2:$B$170,D14,Tree!$E$2:$E$170,2)+COUNTIFS(Tree!$B$2:$B$170,D14,Tree!$E$2:$E$170,3) | G14: Added from the transcript | I14: person
B17: The checks read the Feature discovery, Coverage matrix and Competitors sheets, so they test the data, not just the schema.
B18: Step 04 NFR Discovery: playbook map
B19: Playbook column | C19: Playbook words | D19: Section ID | E19: Section | F19: Parameters (L2+L3) | G19: Live check | H19: Value | I19: Result
B20: Purpose | C20: Fix measurable quality targets before the design locks them out | D20: SEC-10 | E20: =INDEX(Tree!$C$2:$C$170,MATCH(D20,Tree!$B$2:$B$170,0)) | F20: =COUNTIFS(Tree!$B$2:$B$170,D20,Tree!$E$2:$E$170,2)+COUNTIFS(Tree!$B$2:$B$170,D20,Tree!$E$2:$E$170,3) | G20: Approved NFRs with a target recorded (needs 1 or more) | H20: =COUNTIFS('NFR register'!$K$4:$K$29,"Set",'NFR register'!$R$4:$R$29,"<>Proposed") | I20: =IF(H20>=1,"PASS","FAIL")
B21: Do | C21: Set targets for scale, response time, availability, security, privacy, compliance and accessibility | D21: SEC-09 | E21: =INDEX(Tree!$C$2:$C$170,MATCH(D21,Tree!$B$2:$B$170,0)) | F21: =COUNTIFS(Tree!$B$2:$B$170,D21,Tree!$E$2:$E$170,2)+COUNTIFS(Tree!$B$2:$B$170,D21,Tree!$E$2:$E$170,3) | G21: Of those 7 areas, how many have no approved NFR (needs 0) | H21: =(COUNTIFS('NFR register'!$C$4:$C$29,"Scale",'NFR register'!$R$4:$R$29,"<>Proposed")=0)+(COUNTIFS('NFR register'!$C$4:$C$29,"Performance",'NFR register'!$R$4:$R$29,"<>Proposed")=0)+(COUNTIFS('NFR register'!$C$4:$C$29,"Availability and recovery",'NFR register'!$R$4:$R$29,"<>Proposed")=0)+(COUNTIFS('NFR register'!$C$4:$C$29,"Security",'NFR register'!$R$4:$R$29,"<>Proposed")=0)+(COUNTIFS('NFR register'!$C$4:$C$29,"Privacy",'NFR register'!$R$4:$R$29,"<>Proposed")=0)+(COUNTIFS('NFR register'!$C$4:$C$29,"Compliance",'NFR register'!$R$4:$R$29,"<>Proposed")=0)+(COUNTIFS('NFR register'!$C$4:$C$29,"Accessibility",'NFR register'!$R$4:$R$29,"<>Proposed")=0) | I21: =IF(H21=0,"PASS","FAIL")
B22: Produce | C22: NFR register: ID, metric, target, how it is measured | D22: SEC-11 | E22: =INDEX(Tree!$C$2:$C$170,MATCH(D22,Tree!$B$2:$B$170,0)) | F22: =COUNTIFS(Tree!$B$2:$B$170,D22,Tree!$E$2:$E$170,2)+COUNTIFS(Tree!$B$2:$B$170,D22,Tree!$E$2:$E$170,3) | G22: Approved NFRs in the register | H22: =COUNTIFS('NFR register'!$R$4:$R$29,"<>Proposed") | I22: =IF(H22>=1,"PASS","FAIL")
B23: Done when | C23: Every NFR has a number ... | D23: SEC-10 | E23: =INDEX(Tree!$C$2:$C$170,MATCH(D23,Tree!$B$2:$B$170,0)) | F23: =COUNTIFS(Tree!$B$2:$B$170,D23,Tree!$E$2:$E$170,2)+COUNTIFS(Tree!$B$2:$B$170,D23,Tree!$E$2:$E$170,3) | G23: Approved NFRs without a numeric target (needs 0) | H23: =COUNTIFS('NFR register'!$R$4:$R$29,"<>Proposed")-COUNTIFS('NFR register'!$I$4:$I$29,"<>",'NFR register'!$R$4:$R$29,"<>Proposed") | I23: =IF(H23=0,"PASS","FAIL")
B24: Done when | C24: ... and a test method | D24: SEC-11 | E24: =INDEX(Tree!$C$2:$C$170,MATCH(D24,Tree!$B$2:$B$170,0)) | F24: =COUNTIFS(Tree!$B$2:$B$170,D24,Tree!$E$2:$E$170,2)+COUNTIFS(Tree!$B$2:$B$170,D24,Tree!$E$2:$E$170,3) | G24: Approved NFRs without a test method (needs 0) | H24: =COUNTIFS('NFR register'!$M$4:$M$29,"Not yet defined",'NFR register'!$R$4:$R$29,"<>Proposed") | I24: =IF(H24=0,"PASS","FAIL")
B25: Go deeper | C25: Derive targets from volumes, not guesses | D25: SEC-12 | E25: =INDEX(Tree!$C$2:$C$170,MATCH(D25,Tree!$B$2:$B$170,0)) | F25: =COUNTIFS(Tree!$B$2:$B$170,D25,Tree!$E$2:$E$170,2)+COUNTIFS(Tree!$B$2:$B$170,D25,Tree!$E$2:$E$170,3) | G25: Approved NFRs with no derivation recorded (needs 0) | H25: =COUNTIFS('NFR register'!$O$4:$O$29,"Not yet derived",'NFR register'!$R$4:$R$29,"<>Proposed") | I25: =IF(H25=0,"PASS","FAIL")
B26: Go deeper | C26: Name the regulations that apply, such as the DPDP Act 2023 | D26: SEC-12 | E26: =INDEX(Tree!$C$2:$C$170,MATCH(D26,Tree!$B$2:$B$170,0)) | F26: =COUNTIFS(Tree!$B$2:$B$170,D26,Tree!$E$2:$E$170,2)+COUNTIFS(Tree!$B$2:$B$170,D26,Tree!$E$2:$E$170,3) | G26: Approved NFRs that name a regulation (needs 1 or more) | H26: =COUNTIFS('NFR register'!$Q$4:$Q$29,"?*",'NFR register'!$R$4:$R$29,"<>Proposed") | I26: =IF(H26>=1,"PASS","FAIL")
B30: Step 04 results are meant to show the gaps: a FAIL here is something still to fix in the NFR register, not a fault in the schema.
B32: Step 01 Requirement Analysis Docket: playbook map
B33: Playbook column | C33: Playbook words | D33: Section ID | E33: Section | F33: Parameters (L2+L3) | G33: Live check | H33: Value | I33: Result
B34: Purpose | C34: Turn the raw brief into a structured, unambiguous problem statement | D34: SEC-14 | E34: =INDEX(Tree!$C$2:$C$170,MATCH(D34,Tree!$B$2:$B$170,0)) | F34: =COUNTIFS(Tree!$B$2:$B$170,D34,Tree!$E$2:$E$170,2)+COUNTIFS(Tree!$B$2:$B$170,D34,Tree!$E$2:$E$170,3) | G34: Requirements recorded (needs 1 or more) | H34: =COUNTA('Requirements'!$A$4:$A$111) | I34: =IF(H34>=1,"PASS","FAIL")
B35: Do | C35: Split the brief into goals, scope, out-of-scope, assumptions and open questions | D35: SEC-18 | E35: =INDEX(Tree!$C$2:$C$170,MATCH(D35,Tree!$B$2:$B$170,0)) | F35: =COUNTIFS(Tree!$B$2:$B$170,D35,Tree!$E$2:$E$170,2)+COUNTIFS(Tree!$B$2:$B$170,D35,Tree!$E$2:$E$170,3) | G35: Of those 5 line types, how many have no line (needs 0) | H35: =(COUNTIF('Scope lines'!$C$4:$C$22,"Goal")=0)+(COUNTIF('Scope lines'!$C$4:$C$22,"In scope")=0)+(COUNTIF('Scope lines'!$C$4:$C$22,"Out of scope")=0)+(COUNTIF('Scope lines'!$C$4:$C$22,"Assumption")=0)+(COUNTIF('Scope lines'!$C$4:$C$22,"Open question")=0) | I35: =IF(H35=0,"PASS","FAIL")
B36: Do | C36: Give every requirement an ID | D36: SEC-14 | E36: =INDEX(Tree!$C$2:$C$170,MATCH(D36,Tree!$B$2:$B$170,0)) | F36: =COUNTIFS(Tree!$B$2:$B$170,D36,Tree!$E$2:$E$170,2)+COUNTIFS(Tree!$B$2:$B$170,D36,Tree!$E$2:$E$170,3) | G36: Requirements with no ID or a repeated ID (needs 0) | H36: =COUNTA('Requirements'!$D$4:$D$111)-COUNTA('Requirements'!$A$4:$A$111)+SUMPRODUCT(--(COUNTIF('Requirements'!$A$4:$A$111,'Requirements'!$A$4:$A$111)>1)) | I36: =IF(H36=0,"PASS","FAIL")
B37: Produce | C37: Requirements docket: ID, statement, source ... | D37: SEC-15 | E37: =INDEX(Tree!$C$2:$C$170,MATCH(D37,Tree!$B$2:$B$170,0)) | F37: =COUNTIFS(Tree!$B$2:$B$170,D37,Tree!$E$2:$E$170,2)+COUNTIFS(Tree!$B$2:$B$170,D37,Tree!$E$2:$E$170,3) | G37: Requirements with no source recorded (needs 0) | H37: =COUNTA('Requirements'!$A$4:$A$111)-COUNTIFS('Requirements'!$E$4:$E$111,"<>Not recorded",'Requirements'!$E$4:$E$111,"<>") | I37: =IF(H37=0,"PASS","FAIL")
B38: Produce | C38: ... priority ... | D38: SEC-16 | E38: =INDEX(Tree!$C$2:$C$170,MATCH(D38,Tree!$B$2:$B$170,0)) | F38: =COUNTIFS(Tree!$B$2:$B$170,D38,Tree!$E$2:$E$170,2)+COUNTIFS(Tree!$B$2:$B$170,D38,Tree!$E$2:$E$170,3) | G38: Requirements with no priority (needs 0) | H38: =COUNTA('Requirements'!$A$4:$A$111)-COUNTA('Requirements'!$H$4:$H$111) | I38: =IF(H38=0,"PASS","FAIL")
B39: Produce | C39: ... ambiguity notes | D39: SEC-16 | E39: =INDEX(Tree!$C$2:$C$170,MATCH(D39,Tree!$B$2:$B$170,0)) | F39: =COUNTIFS(Tree!$B$2:$B$170,D39,Tree!$E$2:$E$170,2)+COUNTIFS(Tree!$B$2:$B$170,D39,Tree!$E$2:$E$170,3) | G39: Requirements with an ambiguity note (information only) | H39: =COUNTA('Requirements'!$J$4:$J$111) | I39: info
B40: Done when | C40: Every sentence of the brief maps to a requirement ID or an explicit out-of-scope line | D40: SEC-18 | E40: =INDEX(Tree!$C$2:$C$170,MATCH(D40,Tree!$B$2:$B$170,0)) | F40: =COUNTIFS(Tree!$B$2:$B$170,D40,Tree!$E$2:$E$170,2)+COUNTIFS(Tree!$B$2:$B$170,D40,Tree!$E$2:$E$170,3) | G40: Needs the original brief: a person checks | I40: person
B41: Exit gate G1 | C41: Every requirement has an ID and an actor | D41: SEC-15 | E41: =INDEX(Tree!$C$2:$C$170,MATCH(D41,Tree!$B$2:$B$170,0)) | F41: =COUNTIFS(Tree!$B$2:$B$170,D41,Tree!$E$2:$E$170,2)+COUNTIFS(Tree!$B$2:$B$170,D41,Tree!$E$2:$E$170,3) | G41: Requirements with no actor (needs 0) | H41: =COUNTA('Requirements'!$A$4:$A$111)-COUNTA('Requirements'!$G$4:$G$111) | I41: =IF(H41=0,"PASS","FAIL")
B42: Go deeper | C42: Rank open questions by design impact | D42: SEC-18 | E42: =INDEX(Tree!$C$2:$C$170,MATCH(D42,Tree!$B$2:$B$170,0)) | F42: =COUNTIFS(Tree!$B$2:$B$170,D42,Tree!$E$2:$E$170,2)+COUNTIFS(Tree!$B$2:$B$170,D42,Tree!$E$2:$E$170,3) | G42: Open questions recorded (needs 1 or more; the ranking itself is not recorded) | H42: =COUNTIF('Scope lines'!$C$4:$C$22,"Open question") | I42: =IF(H42>=1,"PASS","FAIL")
B44: Step 01 results are meant to show the gaps: source and brief mapping need the original brief.

Sheet Tree
A1: Deliverable | B1: Section ID | C1: Section | D1: Path id | E1: Level | F1: Level name | G1: Name | H1: Definition | I1: Data type | J1: Atomic or derived | K1: Required | L1: Allowed values | M1: Example | N1: Table | O1: Column
A2: Step 03 | B2: SEC-01 | C2: Study Frame | D2: 1 | E2: 1 | F2: Macro | G2: Study Frame | H2: Which product the study is about and how the study was done, so it can be repeated. | N2: study
A3: Step 03 | B3: SEC-01 | C3: Study Frame | D3: 1.1 | E3: 2 | F3: Micro | G3: Study identity | H3: Which product and which analysis stage this study belongs to. | N3: study | O3: (3 columns)
A4: Step 03 | B4: SEC-01 | C4: Study Frame | D4: 1.1.1 | E4: 3 | F4: Nano | G4: Study id | H4: One short code for this study. | I4: id | J4: atomic | K4: required | L4: unique, pattern FDS-nn | M4: FDS-01 | N4: study | O4: study_id
A5: Step 03 | B5: SEC-01 | C5: Study Frame | D5: 1.1.2 | E5: 3 | F5: Nano | G5: Product name | H5: The product the features are discovered for. | I5: text | J5: atomic | K5: required | L5: 1 to 100 characters | M5: Talentra | N5: study | O5: product_name
A6: Step 03 | B6: SEC-01 | C6: Study Frame | D6: 1.1.3 | E6: 3 | F6: Nano | G6: Stage | H6: Which analysis stage this study is. | I6: enum | J6: atomic | K6: required | L6: list: Stage | M6: 03 Feature discovery | N6: study | O6: stage
A7: Step 03 | B7: SEC-01 | C7: Study Frame | D7: 1.2 | E7: 2 | F7: Micro | G7: Study method | H7: How the discovery was done. | N7: study | O7: (3 columns)
A8: Step 03 | B8: SEC-01 | C8: Study Frame | D8: 1.2.1 | E8: 3 | F8: Nano | G8: Method type | H8: Whether people, one LLM or several LLMs did the discovery. | I8: enum | J8: atomic | K8: required | L8: list: MethodType | M8: LLM assisted | N8: study | O8: method_type
A9: Step 03 | B9: SEC-01 | C9: Study Frame | D9: 1.2.2 | E9: 3 | F9: Nano | G9: Schema version | H9: The frozen version of this schema that the study follows. | I9: text | J9: atomic | K9: required | L9: pattern n.n | M9: 1.0 | N9: study | O9: schema_version
A10: Step 03 | B10: SEC-01 | C10: Study Frame | D10: 1.2.3 | E10: 3 | F10: Nano | G10: Study date | H10: The day the study was recorded. | I10: date | J10: atomic | K10: required | L10: date, not in the future | M10: 2026-10-21 | N10: study | O10: study_date
A11: Step 03 | B11: SEC-02 | C11: Competitors Studied | D11: 2 | E11: 1 | F11: Macro | G11: Competitors Studied | H11: The products we compare with. The gate needs at least three of them. | N11: competitor
A12: Step 03 | B12: SEC-02 | C12: Competitors Studied | D12: 2.1 | E12: 2 | F12: Micro | G12: Competitor identity | H12: Which product it is and how much weight its answers carry. | N12: competitor | O12: (4 columns)
A13: Step 03 | B13: SEC-02 | C13: Competitors Studied | D13: 2.1.1 | E13: 3 | F13: Nano | G13: Competitor id | H13: One short code for the competitor. | I13: id | J13: atomic | K13: required | L13: unique, pattern COMP-nn | M13: COMP-03 | N13: competitor | O13: competitor_id
A14: Step 03 | B14: SEC-02 | C14: Competitors Studied | D14: 2.1.2 | E14: 3 | F14: Nano | G14: Competitor name | H14: The name of the competing product. | I14: text | J14: atomic | K14: required | L14: 1 to 100 characters | M14: LinkedIn | N14: competitor | O14: competitor_name
A15: Step 03 | B15: SEC-02 | C15: Competitors Studied | D15: 2.1.3 | E15: 3 | F15: Nano | G15: Product type | H15: What kind of product it is. | I15: enum | J15: atomic | K15: required | L15: list: ProductType | M15: Professional network | N15: competitor | O15: product_type
A16: Step 03 | B16: SEC-02 | C16: Competitors Studied | D16: 2.1.4 | E16: 3 | F16: Nano | G16: Tier | H16: Leader, specialist or reference; only leaders count in the classification rule. | I16: enum | J16: atomic | K16: required | L16: list: Tier | M16: Leader | N16: competitor | O16: tier
A17: Step 03 | B17: SEC-02 | C17: Competitors Studied | D17: 2.2 | E17: 2 | F17: Micro | G17: Study scope | H17: How much of the competitor was studied. | N17: competitor | O17: (3 columns)
A18: Step 03 | B18: SEC-02 | C18: Competitors Studied | D18: 2.2.1 | E18: 3 | F18: Nano | G18: Scope | H18: Whether the competitor is compared for general features or campus features only. | I18: enum | J18: atomic | K18: required | L18: list: StudyScope | M18: General | N18: competitor | O18: study_scope
A19: Step 03 | B19: SEC-02 | C19: Competitors Studied | D19: 2.2.2 | E19: 3 | F19: Nano | G19: Pages studied | H19: How many pages of the competitor were read. | I19: integer | J19: atomic | K19: required | L19: 0 or more | M19: 14 | N19: competitor | O19: pages_studied
A20: Step 03 | B20: SEC-02 | C20: Competitors Studied | D20: 2.2.3 | E20: 3 | F20: Nano | G20: Access level | H20: Whether the pages could be read in full, only as a search summary, or not at all. | I20: enum | J20: atomic | K20: required | L20: list: PageAccess | M20: Read | N20: competitor | O20: access_level
A21: Step 03 | B21: SEC-02 | C21: Competitors Studied | D21: 2.3 | E21: 2 | F21: Micro | G21: Verification | H21: How sure we are about what we know of this competitor. | N21: competitor | O21: (2 columns)
A22: Step 03 | B22: SEC-02 | C22: Competitors Studied | D22: 2.3.1 | E22: 3 | F22: Nano | G22: Last checked on | H22: The day someone last checked the competitor's live pages. | I22: date | J22: atomic | K22: optional | L22: date, not in the future | M22: 2026-10-16 | N22: competitor | O22: last_checked_on
A23: Step 03 | B23: SEC-02 | C23: Competitors Studied | D23: 2.3.2 | E23: 3 | F23: Nano | G23: Evidence status | H23: Public if read on a live page, Known if only recorded in our register. | I23: enum | J23: atomic | K23: required | L23: list: EvidenceStatus | M23: Public | N23: competitor | O23: evidence_status
A24: Step 03 | B24: SEC-03 | C24: Feature Inventory | D24: 3 | E24: 1 | F24: Macro | G24: Feature Inventory | H24: Everything the product must do: one row per feature or per capability inside a feature. | N24: feature
A25: Step 03 | B25: SEC-03 | C25: Feature Inventory | D25: 3.1 | E25: 2 | F25: Micro | G25: Feature identity | H25: Which feature it is and where it sits. | N25: feature | O25: (4 columns)
A26: Step 03 | B26: SEC-03 | C26: Feature Inventory | D26: 3.1.1 | E26: 3 | F26: Nano | G26: Feature id | H26: One fixed code for the feature. | I26: id | J26: atomic | K26: required | L26: unique, pattern FD-nnn | M26: FD-001 | N26: feature | O26: feature_id
A27: Step 03 | B27: SEC-03 | C27: Feature Inventory | D27: 3.1.2 | E27: 3 | F27: Nano | G27: Feature name | H27: A short name in plain words. | I27: text | J27: atomic | K27: required | L27: 1 to 150 characters, unique | M27: Resume headline and profile summary | N27: feature | O27: feature_name
A28: Step 03 | B28: SEC-03 | C28: Feature Inventory | D28: 3.1.3 | E28: 3 | F28: Nano | G28: Feature level | H28: Feature, or capability (one smaller requirement inside a feature). | I28: enum | J28: atomic | K28: required | L28: list: FeatureLevel | M28: Feature | N28: feature | O28: feature_level
A29: Step 03 | B29: SEC-03 | C29: Feature Inventory | D29: 3.1.4 | E29: 3 | F29: Nano | G29: Parent feature id | H29: For a capability, the feature it belongs to. | I29: reference | J29: atomic | K29: conditional | L29: an existing feature_id; required when level is Capability | M29: FD-012 | N29: feature | O29: parent_feature_id
A30: Step 03 | B30: SEC-03 | C30: Feature Inventory | D30: 3.2 | E30: 2 | F30: Micro | G30: Description | H30: What it is, for whom and where it belongs. | N30: feature | O30: (4 columns)
A31: Step 03 | B31: SEC-03 | C31: Feature Inventory | D31: 3.2.1 | E31: 3 | F31: Nano | G31: Plain description | H31: One or two sentences saying what the feature does. | I31: text | J31: atomic | K31: required | L31: 1 to 500 characters | M31: A short headline and a summary of the candidate | N31: feature | O31: description
A32: Step 03 | B32: SEC-03 | C32: Feature Inventory | D32: 3.2.2 | E32: 3 | F32: Nano | G32: Category | H32: The area of the product it belongs to. | I32: enum | J32: atomic | K32: required | L32: list: Category | M32: Profile | N32: feature | O32: category
A33: Step 03 | B33: SEC-03 | C33: Feature Inventory | D33: 3.2.3 | E33: 3 | F33: Nano | G33: Persona | H33: The type of person who uses it most. | I33: enum | J33: atomic | K33: required | L33: list: Persona | M33: Candidate | N33: feature | O33: persona
A34: Step 03 | B34: SEC-03 | C34: Feature Inventory | D34: 3.2.4 | E34: 3 | F34: Nano | G34: Scope | H34: General, campus only, or not observable in competitors. | I34: enum | J34: atomic | K34: required | L34: list: ComparisonScope | M34: General | N34: feature | O34: scope
A35: Step 03 | B35: SEC-03 | C35: Feature Inventory | D35: 3.3 | E35: 2 | F35: Micro | G35: Origin | H35: Where the feature was first found. | N35: feature | O35: (2 columns)
A36: Step 03 | B36: SEC-03 | C36: Feature Inventory | D36: 3.3.1 | E36: 3 | F36: Nano | G36: Source type | H36: What kind of source named the feature. | I36: enum | J36: atomic | K36: required | L36: list: SourceType | M36: Competitor register | N36: feature | O36: source_type
A37: Step 03 | B37: SEC-03 | C37: Feature Inventory | D37: 3.3.2 | E37: 3 | F37: Nano | G37: Source reference | H37: The section or row of that source. | I37: text | J37: atomic | K37: required | L37: 1 to 200 characters | M37: Section 1: Candidate profile | N37: feature | O37: source_reference
A38: Step 03 | B38: SEC-03 | C38: Feature Inventory | D38: 3.4 | E38: 2 | F38: Micro | G38: Scope decision | H38: Whether the feature stays in the product. | N38: feature | O38: (2 columns)
A39: Step 03 | B39: SEC-03 | C39: Feature Inventory | D39: 3.4.1 | E39: 3 | F39: Nano | G39: Scope decision | H39: Keep, defer or drop. | I39: enum | J39: atomic | K39: required | L39: list: ScopeDecision | M39: Keep | N39: feature | O39: scope_decision
A40: Step 03 | B40: SEC-03 | C40: Feature Inventory | D40: 3.4.2 | E40: 3 | F40: Nano | G40: Decision reason | H40: Why a feature was deferred or dropped. | I40: text | J40: atomic | K40: conditional | L40: required when the decision is not Keep | M40: Left out on purpose: placement fees belong to finance | N40: feature | O40: decision_reason
...

Sheet Schema register
A1: Table | B1: Column | C1: Data type | D1: Required | E1: Key | F1: Allowed values | G1: Used by id | H1: Sub-parameter | I1: Section ID | J1: L4 atomic definition
A2: study | B2: study_id | C2: id | D2: required | E2: Primary key | F2: unique, pattern FDS-nn | G2: 1.1.1 | H2: Study id | I2: SEC-01 | J2: Study id: one id value, required; rule: unique, pattern FDS-nn.
A3: study | B3: product_name | C3: text | D3: required | F3: 1 to 100 characters | G3: 1.1.2 | H3: Product name | I3: SEC-01 | J3: Product name: one text value, required; rule: 1 to 100 characters.
A4: study | B4: stage | C4: enum | D4: required | F4: list: Stage | G4: 1.1.3 | H4: Stage | I4: SEC-01 | J4: Stage: one enum value, required; rule: list: Stage.
A5: study | B5: method_type | C5: enum | D5: required | F5: list: MethodType | G5: 1.2.1 | H5: Method type | I5: SEC-01 | J5: Method type: one enum value, required; rule: list: MethodType.
A6: study | B6: schema_version | C6: text | D6: required | F6: pattern n.n | G6: 1.2.2 | H6: Schema version | I6: SEC-01 | J6: Schema version: one text value, required; rule: pattern n.n.
A7: study | B7: study_date | C7: date | D7: required | F7: date, not in the future | G7: 1.2.3 | H7: Study date | I7: SEC-01 | J7: Study date: one date value, required; rule: date, not in the future.
A8: competitor | B8: competitor_id | C8: id | D8: required | E8: Primary key | F8: unique, pattern COMP-nn | G8: 2.1.1 | H8: Competitor id | I8: SEC-02 | J8: Competitor id: one id value, required; rule: unique, pattern COMP-nn.
A9: competitor | B9: study_id | C9: reference | D9: required | E9: Foreign key to study.study_id | H9: Key column, not a parameter | I9: Key link | J9: Key link to the study.
A10: competitor | B10: competitor_name | C10: text | D10: required | F10: 1 to 100 characters | G10: 2.1.2 | H10: Competitor name | I10: SEC-02 | J10: Competitor name: one text value, required; rule: 1 to 100 characters.
A11: competitor | B11: product_type | C11: enum | D11: required | F11: list: ProductType | G11: 2.1.3 | H11: Product type | I11: SEC-02 | J11: Product type: one enum value, required; rule: list: ProductType.
A12: competitor | B12: tier | C12: enum | D12: required | F12: list: Tier | G12: 2.1.4 | H12: Tier | I12: SEC-02 | J12: Tier: one enum value, required; rule: list: Tier.
A13: competitor | B13: study_scope | C13: enum | D13: required | F13: list: StudyScope | G13: 2.2.1 | H13: Scope | I13: SEC-02 | J13: Scope: one enum value, required; rule: list: StudyScope.
A14: competitor | B14: pages_studied | C14: integer | D14: required | F14: 0 or more | G14: 2.2.2 | H14: Pages studied | I14: SEC-02 | J14: Pages studied: one integer value, required; rule: 0 or more.
A15: competitor | B15: access_level | C15: enum | D15: required | F15: list: PageAccess | G15: 2.2.3 | H15: Access level | I15: SEC-02 | J15: Access level: one enum value, required; rule: list: PageAccess.
A16: competitor | B16: last_checked_on | C16: date | D16: optional | F16: date, not in the future | G16: 2.3.1 | H16: Last checked on | I16: SEC-02 | J16: Last checked on: one date value, optional; rule: date, not in the future.
A17: competitor | B17: evidence_status | C17: enum | D17: required | F17: list: EvidenceStatus | G17: 2.3.2 | H17: Evidence status | I17: SEC-02 | J17: Evidence status: one enum value, required; rule: list: EvidenceStatus.
A18: feature | B18: feature_id | C18: id | D18: required | E18: Primary key | F18: unique, pattern FD-nnn | G18: 3.1.1 | H18: Feature id | I18: SEC-03 | J18: Feature id: one id value, required; rule: unique, pattern FD-nnn.
A19: feature | B19: study_id | C19: reference | D19: required | E19: Foreign key to study.study_id | H19: Key column, not a parameter | I19: Key link | J19: Key link to the study.
A20: feature | B20: feature_name | C20: text | D20: required | F20: 1 to 150 characters, unique | G20: 3.1.2 | H20: Feature name | I20: SEC-03 | J20: Feature name: one text value, required; rule: 1 to 150 characters, unique.
A21: feature | B21: feature_level | C21: enum | D21: required | F21: list: FeatureLevel | G21: 3.1.3 | H21: Feature level | I21: SEC-03 | J21: Feature level: one enum value, required; rule: list: FeatureLevel.
A22: feature | B22: parent_feature_id | C22: reference | D22: conditional | F22: an existing feature_id; required when level is Capability | G22: 3.1.4 | H22: Parent feature id | I22: SEC-03 | J22: Parent feature id: one reference value, conditional; rule: an existing feature_id; required when level is Capability.
A23: feature | B23: description | C23: text | D23: required | F23: 1 to 500 characters | G23: 3.2.1 | H23: Plain description | I23: SEC-03 | J23: Plain description: one text value, required; rule: 1 to 500 characters.
A24: feature | B24: category | C24: enum | D24: required | F24: list: Category | G24: 3.2.2 | H24: Category | I24: SEC-03 | J24: Category: one enum value, required; rule: list: Category.
A25: feature | B25: persona | C25: enum | D25: required | F25: list: Persona | G25: 3.2.3 | H25: Persona | I25: SEC-03 | J25: Persona: one enum value, required; rule: list: Persona.
A26: feature | B26: scope | C26: enum | D26: required | F26: list: ComparisonScope | G26: 3.2.4 | H26: Scope | I26: SEC-03 | J26: Scope: one enum value, required; rule: list: ComparisonScope.
A27: feature | B27: source_type | C27: enum | D27: required | F27: list: SourceType | G27: 3.3.1 | H27: Source type | I27: SEC-03 | J27: Source type: one enum value, required; rule: list: SourceType.
A28: feature | B28: source_reference | C28: text | D28: required | F28: 1 to 200 characters | G28: 3.3.2 | H28: Source reference | I28: SEC-03 | J28: Source reference: one text value, required; rule: 1 to 200 characters.
A29: feature | B29: scope_decision | C29: enum | D29: required | F29: list: ScopeDecision | G29: 3.4.1 | H29: Scope decision | I29: SEC-03 | J29: Scope decision: one enum value, required; rule: list: ScopeDecision.
A30: feature | B30: decision_reason | C30: text | D30: conditional | F30: required when the decision is not Keep | G30: 3.4.2 | H30: Decision reason | I30: SEC-03 | J30: Decision reason: one text value, conditional; rule: required when the decision is not Keep.
A31: feature | B31: classification | C31: enum | D31: required | F31: list: Class | G31: 4.1.1 | H31: Classification | I31: SEC-04 | J31: Classification: one enum value, required; rule: list: Class.
... A47: feature | B47: tests_passed | C47: integer | D47: optional | F47: 0 to tests total | G47: 6.3.6 | H47: Tests passed | I47: SEC-06 | J47: Derived: worked out from other columns.
A48: competitor_coverage | B48: feature_id | C48: reference | D48: required | E48: Primary key (part 1) and foreign key to feature.feature_id | F48: an existing feature_id | G48: 5.1.1 | H48: Feature id | I48: SEC-05 | J48: Feature id: one reference value, required; rule: an existing feature_id.
A49: competitor_coverage | B49: competitor_id | C49: reference | D49: required | E49: Primary key (part 2) and foreign key to competitor.competitor_id | F49: an existing competitor_id | G49: 5.1.2 | H49: Competitor id | I49: SEC-05 | J49: Competitor id: one reference value, required; rule: an existing competitor_id.
A50: competitor_coverage | B50: offering | C50: enum | D50: required | F50: list: CellValue | G50: 5.2.1 | H50: Offering | I50: SEC-05 | J50: Offering: one enum value, required; rule: list: CellValue.
A51: competitor_coverage | B51: offering_note | C51: text | D51: optional | F51: 0 to 300 characters | G51: 5.2.2 | H51: Offering note | I51: SEC-05 | J51: Offering note: one text value, optional; rule: 0 to 300 characters.
A52: competitor_coverage | B52: evidence_type | C52: enum | D52: required | F52: list: EvidenceType | G52: 5.3.1 | H52: Evidence type | I52: SEC-05 | J52: Evidence type: one enum value, required; rule: list: EvidenceType.
A53: competitor_coverage | B53: evidence_source | C53: text | D53: required | F53: 1 to 300 characters | G53: 5.3.2 | H53: Evidence source | I53: SEC-05 | J53: Evidence source: one text value, required; rule: 1 to 300 characters.
A54: competitor_coverage | B54: checked_on | C54: date | D54: optional | F54: date, not in the future | G54: 5.3.3 | H54: Checked on | I54: SEC-05 | J54: Checked on: one date value, optional; rule: date, not in the future.
A55: feature_requirement | B55: feature_id | C55: reference | D55: required | E55: Primary key (part 1) and foreign key to feature.feature_id | F55: an existing feature_id | G55: 6.1.1 | H55: Feature id | I55: SEC-06 | J55: Feature id: one reference value, required; rule: an existing feature_id.
...

Sheet Allowed values
A1: List | B1: Value | C1: Meaning | D1: Used by sub-parameter | E1: Section ID
A2: Stage | B2: 01 Requirement analysis | C2: Stage 01: the requirement analysis docket. | D2: 1.1.3 Stage | E2: SEC-01
A3: Stage | B3: 02 Stakeholder personas and roles | C3: Stage 02: who uses the product and what each role may do. | E3: SEC-01
A4: Stage | B4: 03 Feature discovery | C4: Stage 03: this schema. Find what the product must do and what market leaders already do. | E4: SEC-01
A5: Stage | B5: 04 Non-functional requirements | C5: Stage 04: scale, speed, security, privacy, recovery targets. | E5: SEC-01
A6: MethodType | B6: Human only | C6: Every parameter value was written by a person. | D6: 1.2.1 Method type | E6: SEC-01
A7: MethodType | B7: LLM assisted | C7: A language model proposed values and a person checked every one. | E7: SEC-01
A8: MethodType | B8: Multi-LLM consolidated | C8: Two or more models or designers worked alone and a person consolidated the better parts. | E8: SEC-01
A9: ProductType | B9: Job portal | C9: A site where employers post jobs and candidates search and apply. | D9: 2.1.3 Product type | E9: SEC-02
A10: ProductType | B10: Professional network | C10: A social network whose members also search for jobs and people. | E10: SEC-02
A11: ProductType | B11: Campus hiring platform | C11: A platform for colleges and fresher hiring. | E11: SEC-02
A12: ProductType | B12: Other | C12: Any other kind of product. Say which in the reason studied. | E12: SEC-02
A13: Tier | B13: Leader | C13: A studied market leader. It counts in the classification rule. | D13: 2.1.4 Tier | E13: SEC-02
A14: Tier | B14: Specialist | C14: A leader in one scope only (for example campus). It counts only for that scope. | E14: SEC-02
A15: Tier | B15: Reference | C15: Studied for ideas. It does not count in the classification rule. | E15: SEC-02
A16: StudyScope | B16: General | C16: Studied for general features. | D16: 2.2.1 Scope | E16: SEC-02
A17: StudyScope | B17: Campus | C17: Studied for campus features only. | E17: SEC-02
A18: PageAccess | B18: Read | C18: The page was opened and read. | D18: 2.2.3 Access level | E18: SEC-02
A19: PageAccess | B19: Search summary only | C19: Only a search-engine summary of the page could be read. | E19: SEC-02
A20: PageAccess | B20: Not readable | C20: The page refused download or could not be read. | E20: SEC-02
A21: EvidenceStatus | B21: Public | C21: Checked on a public page of the product. | D21: 2.3.2 Evidence status; 4.2.2 Evidence status; 7.2.2 Evidence status | E21: SEC-02
A22: EvidenceStatus | B22: Known | C22: General knowledge, not checked on the live product. | E22: SEC-02
A23: EvidenceStatus | B23: Mixed | C23: Some cells Public and some Known. | E23: SEC-02
A24: EvidenceStatus | B24: Own design | C24: No competitor claim; our own design. | E24: SEC-02
A25: EvidenceStatus | B25: Search summary only | C25: Only a search-result summary of the page was seen | E25: SEC-02
A26: EvidenceStatus | B26: Verification log | C26: Taken from the verification log; not marked per row | E26: SEC-02
A27: EvidenceStatus | B27: Gap table | C27: Taken from the gap table; not marked per row | E27: SEC-02
A28: FeatureLevel | B28: Feature | C28: Something a user can see or do. It is compared with competitors. | D28: 3.1.3 Feature level | E28: SEC-03
A29: FeatureLevel | B29: Capability | C29: One requirement inside a feature that has several. It inherits the feature's class, matrix cells and verdict. | E29: SEC-03
A30: Category | B30: Profile | C30: The candidate's data: identity, skills, history, documents, visibility. | D30: 3.2.2 Category | E30: SEC-03
A31: Category | B31: Search | C31: Finding candidates or jobs by filters or keywords. | E31: SEC-03
A32: Category | B32: Jobs | C32: Posting and managing job requirements. | E32: SEC-03
A33: Category | B33: Applications | C33: Applying, the pipeline of statuses, withdrawing. | E33: SEC-03
A34: Category | B34: Hiring workflow | C34: Shortlists, interviews, offers, joining. | E34: SEC-03
A35: Category | B35: Consultants and sourcing | C35: Consultant requests, submissions, outreach. | E35: SEC-03
A36: Category | B36: Campus | C36: Campus drives and fresher hiring. | E36: SEC-03
A37: Category | B37: Gig | C37: Short assignments, bids and fulfilment. | E37: SEC-03
A38: Category | B38: Licences, subscriptions and wallet | C38: Seats, devices, plans, credits, payments, downloads. | E38: SEC-03
A39: Category | B39: Notifications and community | C39: Messages, preferences, posts and moderation. | E39: SEC-03
A40: Category | B40: Analytics | C40: Reports and marts built from the live data. | E40: SEC-03
...

Sheet Feature discovery
A1: Output document (draft, deliverable c): the 176 features and capabilities in the original column layout. Five columns were normalised to the schema's allowed values; the wording as first recorded is kept in the last column.
A3: ID | B3: Level | C3: Parent | D3: Feature | E3: Plain description | F3: Category | G3: Persona | H3: Source type | I3: Source reference | J3: Scope | K3: Classification | L3: Class basis | M3: Reason | N3: Confidence | O3: Evidence status | P3: Our coverage | Q3: Verdict | R3: Verdict source | S3: Trace status | T3: Note | U3: Rule check | V3: Recorded wording before normalising
A4: FD-001 | B4: Feature | D4: Resume headline and profile summary | E4: A short headline and a summary of the candidate, with the language of the text. | F4: Profile | G4: Candidate | H4: Competitor register | I4: Section 1: Candidate profile (row 1) | J4: General | K4: MUST-HAVE | L4: Competitor matrix rule | M4: 3 of 3 studied leaders offer it (Naukri, Monster, LinkedIn); 0 not verified. | N4: Firm | O4: Public | P4: Built and tested | Q4: Matches | R4: Register | S4: Traced | U4: OK | V4: Trace status: Traced to requirement
A5: FD-002 | B5: Feature | D5: Employment history with designation, organisation, duration, description | E5: Jobs held, with designation, organisation, dates and description, and the notice period. | F5: Profile | G5: Candidate | H5: Competitor register | I5: Section 1: Candidate profile (row 2) | J5: General | K5: MUST-HAVE | L5: Competitor matrix rule | M5: 3 of 3 studied leaders offer it (Naukri, Monster, LinkedIn); 0 not verified. | N5: Firm | O5: Public | P5: Built and tested | Q5: Matches | R5: Register | S5: Traced | U5: OK | V5: Trace status: Traced to requirement
A6: FD-003 | B6: Feature | D6: Education | E6: Qualifications with institution, grade and the grading scale used. | F6: Profile | G6: Candidate | H6: Competitor register | I6: Section 1: Candidate profile (row 3) | J6: General | K6: MUST-HAVE | L6: Competitor matrix rule | M6: 3 of 3 studied leaders offer it (Naukri, Monster, LinkedIn); 0 not verified. | N6: Firm | O6: Public | P6: Built and tested | Q6: Matches | R6: Register | S6: Traced | U6: OK | V6: Trace status: Traced to requirement
A7: FD-004 | B7: Feature | D7: Key skills | E7: Skills with level, years of use, last year used and where the skill came from. | F7: Profile | G7: Candidate | H7: Competitor register | I7: Section 1: Candidate profile (row 4) | J7: General | K7: MUST-HAVE | L7: Competitor matrix rule | M7: 3 of 3 studied leaders offer it (Naukri, Monster, LinkedIn); 0 not verified. | N7: Firm | O7: Public | P7: Built and tested | Q7: Exceeds | R7: Register | S7: Traced | U7: OK | V7: Trace status: Traced to requirement
A8: FD-005 | B8: Feature | D8: IT skills with software version | E8: A skill can carry the software version, so a search can tell one version of a tool from another. | F8: Profile | G8: Candidate | H8: Competitor register | I8: Section 1: Candidate profile (row 5) | J8: General | K8: DIFFERENTIATOR | L8: Competitor matrix rule | M8: 1 of 3 studied leaders offer it (Naukri); 0 not verified. | N8: Firm | O8: Known | P8: Built and tested | Q8: Matches | R8: Register | S8: Traced | U8: OK | V8: Trace status: Traced to requirement
A9: FD-006 | B9: Feature | D9: Languages | E9: Languages with separate read, write and speak levels. | F9: Profile | G9: Candidate | H9: Competitor register | I9: Section 1: Candidate profile (row 6) | J9: General | K9: SHOULD-HAVE | L9: Competitor matrix rule | M9: 1 of 3 studied leaders offer it (LinkedIn); 1 not verified. | N9: Provisional | O9: Public | P9: Built and tested | Q9: Exceeds | R9: Register | S9: Traced | U9: OK | V9: Trace status: Traced to requirement
A10: FD-007 | B10: Feature | D10: Certifications and licences | E10: Certificates and licences with a credential reference and an expiry date. | F10: Profile | G10: Candidate | H10: Competitor register | I10: Section 1: Candidate profile (row 7) | J10: General | K10: MUST-HAVE | L10: Competitor matrix rule | M10: 3 of 3 studied leaders offer it (Naukri, Monster, LinkedIn); 0 not verified. | N10: Firm | O10: Public | P10: Built and tested | Q10: Matches | R10: Register | S10: Traced | U10: OK | V10: Trace status: Traced to requirement
A11: FD-008 | B11: Feature | D11: Projects | E11: Projects done on a job or as gig work, with the skills used. | F11: Profile | G11: Candidate | H11: Competitor register | I11: Section 1: Candidate profile (row 8) | J11: General | K11: SHOULD-HAVE | L11: Competitor matrix rule | M11: 2 of 3 studied leaders offer it (Naukri, LinkedIn); 0 not verified. | N11: Firm | O11: Public | P11: Built and tested | Q11: Matches | R11: Register | S11: Traced | U11: OK | V11: Trace status: Traced to requirement
A12: FD-009 | B12: Feature | D12: Accomplishments: publications, patents, work samples | E12: Publications, patents, honours and work samples, kept as typed accomplishments. | F12: Profile | G12: Candidate | H12: Competitor register | I12: Section 1: Candidate profile (row 9) | J12: General | K12: SHOULD-HAVE | L12: Competitor matrix rule | M12: 2 of 3 studied leaders offer it (Naukri, LinkedIn); 0 not verified. | N12: Firm | O12: Public | P12: Built and tested | Q12: Matches | R12: Register | S12: Traced | U12: OK | V12: Trace status: Traced to requirement
A13: FD-010 | B13: Feature | D13: Volunteering and organisations | E13: Volunteer work and organisations the candidate belongs to. | F13: Profile | G13: Candidate | H13: Competitor register | I13: Section 1: Candidate profile (row 10) | J13: General | K13: DIFFERENTIATOR | L13: Competitor matrix rule | M13: 1 of 3 studied leaders offer it (LinkedIn); 0 not verified. | N13: Firm | O13: Public | P13: Built and tested | Q13: Matches | R13: Register | S13: Traced | U13: OK | V13: Trace status: Traced to requirement
A14: FD-011 | B14: Feature | D14: Recommendations and endorsements | E14: Other people recommend or endorse a candidate on the profile. | F14: Profile | G14: Candidate | H14: Competitor register | I14: Section 1: Candidate profile (row 11) | J14: General | K14: DIFFERENTIATOR | L14: Competitor matrix rule | M14: 1 of 3 studied leaders offer it (LinkedIn); 0 not verified. | N14: Firm | O14: Public | P14: Not built | Q14: Falls short | R14: Register | S14: New insight | U14: OK | V14: Trace status: NEW INSIGHT
A15: FD-012 | B15: Feature | D15: Courses | E15: Courses taken, with progress, as part of the profile. | F15: Profile | G15: Candidate | H15: Competitor register | I15: Section 1: Candidate profile (row 12) | J15: General | K15: SHOULD-HAVE | L15: Competitor matrix rule | M15: 1 of 3 studied leaders offer it (LinkedIn); 1 not verified. | N15: Provisional | O15: Public | P15: Built | Q15: Exceeds | R15: Register | S15: Traced | U15: OK | V15: Trace status: Traced to requirement
... A53: FD-050 | B53: Feature | D53: Gig marketplace with windows, pricing, one-way bids, external fulfilment (LinkedIn has a Services marketplace, with no windows or bids) | E53: Short tasks with a time window, a price, one-way bids and an outside fulfilment system. | F53: Gig | G53: Gig worker | H53: Competitor register | I53: Section 6: Things in Talentra that these products do not show to users (row 50) | J53: Not observable | K53: DIFFERENTIATOR | L53: Declared market-wide | M53: Register section 6: LinkedIn has a Services marketplace with no windows or bids; no other studied product shows one (evidence Known) | N53: Declared | O53: Known | P53: Built | Q53: Exceeds | R53: Register | S53: Traced | U53: declared | V53: Class basis: Register section 6: LinkedIn has a Services marketplace with no windows or bids; no other studied product shows one (evidence Known) | Confidence: Declared (not observable) | Trace status: Traced to requirement
A54: FD-051 | B54: Feature | D54: Consultant marketplace: freelance recruiters source for jobs open to consultants | E54: A consultant works only the jobs open to consultants, through a request the employer approves, with fee terms. | F54: Consultants and sourcing | G54: Consultant | H54: Competitor register | I54: Section 6: Things in Talentra that these products do not show to users (row 51) | J54: Not observable | K54: MUST-HAVE | L54: Brief demands | M54: Brief demands: a consultant acts only on requirements open to consultants (decision SO1) | N54: Declared | O54: Known | P54: Built and tested | Q54: Exceeds | R54: Register | S54: Traced | T54: Register verdict: Exceeds on the rule that a consultant acts only on open requirements; falls short on settlement and protection | U54: declared | V54: Class basis: Brief demands: a consultant acts only on requirements open to consultants (decision SO1) | Confidence: Declared (not observable) | Trace status: Traced to requirement
A55: FD-052 | B55: Feature | D55: Candidate can block employers, recruiters and consultants by party type (LinkedIn blocks any member) | E55: A candidate blocks an organisation or a person, and the blocked side cannot see the candidate. | F55: Privacy and security | G55: Candidate | H55: Competitor register | I55: Section 6: Things in Talentra that these products do not show to users (row 52) | J55: Not observable | K55: MUST-HAVE | L55: Brief demands | M55: Brief demands: the blocked-party rule (decision A7) | N55: Declared | O55: Known | P55: Built and tested | Q55: Exceeds | R55: Register | S55: Traced | U55: declared | V55: Class basis: Brief demands: the blocked-party rule (decision A7) | Confidence: Declared (not observable) | Trace status: Traced to requirement
